Bot started
2025-10-05 15:13:33,845 - ERROR - __main__ - Failed to create client: HTTPSConnectionPool(host='testnet.binance.vision', port=443): Max retries exceeded with url: /api/v3/ping (Caused by NameResolutionError("<urllib3.connection.HTTPSConnection object at 0x0000025F830291D0>: Failed to resolve 'testnet.binance.vision' ([Errno 11001] getaddrinfo failed)"))
[ERROR] HTTPSConnectionPool(host='testnet.binance.vision', port=443): Max retries exceeded with url: /api/v3/ping (Caused by NameResolutionError("<urllib3.connection.HTTPSConnection object at 0x0000025F830291D0>: Failed to resolve 'testnet.binance.vision' ([Errno 11001] getaddrinfo failed)"))
info failed)"))
Traceback (most recent call last):
  File "D:\binance_ats_clone\obaidur-binance-ats-main\.venv\.venv\Lib\site-packages\urllib3\connection.py", line 198, in _new_conn
    sock = connection.create_connection(
        (self._dns_host, self.port),
    ...<2 lines>...
        socket_options=self.socket_options,
    )
  File "D:\binance_ats_clone\obaidur-binance-ats-main\.venv\.venv\Lib\site-packages\urllib3\util\connection.py", line 60, in create_connection
    for res in socket.getaddrinfo(host, port, family, socket.SOCK_STREAM):
               ~~~~~~~~~~~~~~~~~~^^^^^^^^^^^^^^^^^^^^^^^^^^^^^^^^^^^^^^^^
  File "C:\Python313\Lib\socket.py", line 977, in getaddrinfo
    for res in _socket.getaddrinfo(host, port, family, type, proto, flags):
               ~~~~~~~~~~~~~~~~~~~^^^^^^^^^^^^^^^^^^^^^^^^^^^^^^^^^^^^^^^^
socket.gaierror: [Errno 11001] getaddrinfo failed

The above exception was the direct cause of the following exception:

Traceback (most recent call last):
  File "D:\binance_ats_clone\obaidur-binance-ats-main\.venv\.venv\Lib\site-packages\urllib3\connectionpool.py", line 787, in urlopen
    response = self._make_request(
        conn,
    ...<10 lines>...
        **response_kw,
    )
  File "D:\binance_ats_clone\obaidur-binance-ats-main\.venv\.venv\Lib\site-packages\urllib3\connectionpool.py", line 488, in _make_request
    raise new_e
  File "D:\binance_ats_clone\obaidur-binance-ats-main\.venv\.venv\Lib\site-packages\urllib3\connectionpool.py", line 464, in _make_request
    self._validate_conn(conn)
    ~~~~~~~~~~~~~~~~~~~^^^^^^
  File "D:\binance_ats_clone\obaidur-binance-ats-main\.venv\.venv\Lib\site-packages\urllib3\connectionpool.py", line 1093, in _validate_conn
    conn.connect()
    ~~~~~~~~~~~~^^
  File "D:\binance_ats_clone\obaidur-binance-ats-main\.venv\.venv\Lib\site-packages\urllib3\connection.py", line 753, in connect
    self.sock = sock = self._new_conn()
                       ~~~~~~~~~~~~~~^^
  File "D:\binance_ats_clone\obaidur-binance-ats-main\.venv\.venv\Lib\site-packages\urllib3\connection.py", line 205, in _new_conn
    raise NameResolutionError(self.host, self, e) from e
urllib3.exceptions.NameResolutionError: <urllib3.connection.HTTPSConnection object at 0x0000025F830291D0>: Failed to resolve 'testnet.binance.vision' ([Errno 11001] getaddrinfo failed)

The above exception was the direct cause of the following exception:

Traceback (most recent call last):
  File "D:\binance_ats_clone\obaidur-binance-ats-main\.venv\.venv\Lib\site-packages\requests\adapters.py", line 644, in send
    resp = conn.urlopen(
        method=request.method,
    ...<9 lines>...
        chunked=chunked,
    )
  File "D:\binance_ats_clone\obaidur-binance-ats-main\.venv\.venv\Lib\site-packages\urllib3\connectionpool.py", line 841, in urlopen
    retries = retries.increment(
        method, url, error=new_e, _pool=self, _stacktrace=sys.exc_info()[2]
    )
  File "D:\binance_ats_clone\obaidur-binance-ats-main\.venv\.venv\Lib\site-packages\urllib3\util\retry.py", line 519, in increment
    raise MaxRetryError(_pool, url, reason) from reason  # type: ignore[arg-type]
    ^^^^^^^^^^^^^^^^^^^^^^^^^^^^^^^^^^^^^^^^^^^^^^^^^^^
urllib3.exceptions.MaxRetryError: HTTPSConnectionPool(host='testnet.binance.vision', port=443): Max retries exceeded with url: /api/v3/ping (Caused by NameResolutionError("<urllib3.connection.HTTPSConnection object at 0x0000025F830291D0>: Failed to resolve 'testnet.binance.vision' ([Errno 11001] getaddrinfo failed)"))

During handling of the above exception, another exception occurred:

Traceback (most recent call last):
  File "d:\binance_ats_clone\obaidur-binance-ats-main\src\bot.py", line 318, in run
    client = SafeClient(api_key, api_secret, testnet=use_testnet)
  File "d:\binance_ats_clone\obaidur-binance-ats-main\src\safe_client.py", line 74, in __init__
    self._client = Client(api_key, api_secret, testnet=testnet)
                   ~~~~~~^^^^^^^^^^^^^^^^^^^^^^^^^^^^^^^^^^^^^^
  File "D:\binance_ats_clone\obaidur-binance-ats-main\.venv\.venv\Lib\site-packages\binance\client.py", line 51, in __init__
    self.ping()
    ~~~~~~~~~^^
  File "D:\binance_ats_clone\obaidur-binance-ats-main\.venv\.venv\Lib\site-packages\binance\client.py", line 344, in ping
    return self._get("ping", version=self.PRIVATE_API_VERSION)
           ~~~~~~~~~^^^^^^^^^^^^^^^^^^^^^^^^^^^^^^^^^^^^^^^^^^
  File "D:\binance_ats_clone\obaidur-binance-ats-main\.venv\.venv\Lib\site-packages\binance\client.py", line 180, in _get
    return self._request_api("get", path, signed, version, **kwargs)
           ~~~~~~~~~~~~~~~~~^^^^^^^^^^^^^^^^^^^^^^^^^^^^^^^^^^^^^^^^
  File "D:\binance_ats_clone\obaidur-binance-ats-main\.venv\.venv\Lib\site-packages\binance\client.py", line 117, in _request_api
    return self._request(method, uri, signed, **kwargs)
           ~~~~~~~~~~~~~^^^^^^^^^^^^^^^^^^^^^^^^^^^^^^^
  File "D:\binance_ats_clone\obaidur-binance-ats-main\.venv\.venv\Lib\site-packages\binance\client.py", line 88, in _request
    self.response = getattr(self.session, method)(uri, headers=headers, data=data, **kwargs)
                    ~~~~~~~~~~~~~~~~~~~~~~~~~~~~~^^^^^^^^^^^^^^^^^^^^^^^^^^^^^^^^^^^^^^^^^^^
  File "D:\binance_ats_clone\obaidur-binance-ats-main\.venv\.venv\Lib\site-packages\requests\sessions.py", line 602, in get
    return self.request("GET", url, **kwargs)
           ~~~~~~~~~~~~^^^^^^^^^^^^^^^^^^^^^^
  File "D:\binance_ats_clone\obaidur-binance-ats-main\.venv\.venv\Lib\site-packages\requests\sessions.py", line 589, in request
    resp = self.send(prep, **send_kwargs)
  File "D:\binance_ats_clone\obaidur-binance-ats-main\.venv\.venv\Lib\site-packages\requests\sessions.py", line 703, in send
    r = adapter.send(request, **kwargs)
  File "D:\binance_ats_clone\obaidur-binance-ats-main\.venv\.venv\Lib\site-packages\requests\adapters.py", line 677, in send
    raise ConnectionError(e, request=request)
requests.exceptions.ConnectionError: HTTPSConnectionPool(host='testnet.binance.vision', port=443): Max retries exceeded with url: /api/v3/ping (Caused by NameResolutionError("<urllib3.connection.HTTPSConnection object at 0x0000025F830291D0>: Failed to resolve 'testnet.binance.vision' ([Errno 11001] getaddrinfo failed)"))
[ERROR] HTTPSConnectionPool(host='testnet.binance.vision', port=443): Max retries exceeded with url: /api/v3/ping (Caused by NameResolutionError("<urllib3.connection.HTTPSConnection object at 0x0000025F830291D0>: Failed to resolve 'testnet.binance.vision' ([Errno 11001] getaddrinfo failed)"))
Traceback (most recent call last):
  File "D:\binance_ats_clone\obaidur-binance-ats-main\.venv\.venv\Lib\site-packages\urllib3\connection.py", line 198, in _new_conn
    sock = connection.create_connection(
        (self._dns_host, self.port),
    ...<2 lines>...
        socket_options=self.socket_options,
    )
  File "D:\binance_ats_clone\obaidur-binance-ats-main\.venv\.venv\Lib\site-packages\urllib3\util\connection.py", line 60, in create_connection
    for res in socket.getaddrinfo(host, port, family, socket.SOCK_STREAM):
               ~~~~~~~~~~~~~~~~~~^^^^^^^^^^^^^^^^^^^^^^^^^^^^^^^^^^^^^^^^
  File "C:\Python313\Lib\socket.py", line 977, in getaddrinfo
    for res in _socket.getaddrinfo(host, port, family, type, proto, flags):
               ~~~~~~~~~~~~~~~~~~~^^^^^^^^^^^^^^^^^^^^^^^^^^^^^^^^^^^^^^^^
socket.gaierror: [Errno 11001] getaddrinfo failed

The above exception was the direct cause of the following exception:

Traceback (most recent call last):
  File "D:\binance_ats_clone\obaidur-binance-ats-main\.venv\.venv\Lib\site-packages\urllib3\connectionpool.py", line 787, in urlopen
    response = self._make_request(
        conn,
    ...<10 lines>...
        **response_kw,
    )
  File "D:\binance_ats_clone\obaidur-binance-ats-main\.venv\.venv\Lib\site-packages\urllib3\connectionpool.py", line 488, in _make_request
    raise new_e
  File "D:\binance_ats_clone\obaidur-binance-ats-main\.venv\.venv\Lib\site-packages\urllib3\connectionpool.py", line 464, in _make_request
    self._validate_conn(conn)
    ~~~~~~~~~~~~~~~~~~~^^^^^^
  File "D:\binance_ats_clone\obaidur-binance-ats-main\.venv\.venv\Lib\site-packages\urllib3\connectionpool.py", line 1093, in _validate_conn
    conn.connect()
    ~~~~~~~~~~~~^^
  File "D:\binance_ats_clone\obaidur-binance-ats-main\.venv\.venv\Lib\site-packages\urllib3\connection.py", line 753, in connect
    self.sock = sock = self._new_conn()
                       ~~~~~~~~~~~~~~^^
  File "D:\binance_ats_clone\obaidur-binance-ats-main\.venv\.venv\Lib\site-packages\urllib3\connection.py", line 205, in _new_conn
    raise NameResolutionError(self.host, self, e) from e
urllib3.exceptions.NameResolutionError: <urllib3.connection.HTTPSConnection object at 0x0000025F830291D0>: Failed to resolve 'testnet.binance.vision' ([Errno 11001] getaddrinfo failed)

The above exception was the direct cause of the following exception:

Traceback (most recent call last):
  File "D:\binance_ats_clone\obaidur-binance-ats-main\.venv\.venv\Lib\site-packages\requests\adapters.py", line 644, in send
    resp = conn.urlopen(
        method=request.method,
    ...<9 lines>...
        chunked=chunked,
    )
  File "D:\binance_ats_clone\obaidur-binance-ats-main\.venv\.venv\Lib\site-packages\urllib3\connectionpool.py", line 841, in urlopen
    retries = retries.increment(
        method, url, error=new_e, _pool=self, _stacktrace=sys.exc_info()[2]
    )
  File "D:\binance_ats_clone\obaidur-binance-ats-main\.venv\.venv\Lib\site-packages\urllib3\util\retry.py", line 519, in increment
    raise MaxRetryError(_pool, url, reason) from reason  # type: ignore[arg-type]
    ^^^^^^^^^^^^^^^^^^^^^^^^^^^^^^^^^^^^^^^^^^^^^^^^^^^
urllib3.exceptions.MaxRetryError: HTTPSConnectionPool(host='testnet.binance.vision', port=443): Max retries exceeded with url: /api/v3/ping (Caused by NameResolutionError("<urllib3.connection.HTTPSConnection object at 0x0000025F830291D0>: Failed to resolve 'testnet.binance.vision' ([Errno 11001] getaddrinfo failed)"))

During handling of the above exception, another exception occurred:

Traceback (most recent call last):
  File "d:\binance_ats_clone\obaidur-binance-ats-main\src\bot.py", line 441, in <module>
    run()
    ~~~^^
  File "d:\binance_ats_clone\obaidur-binance-ats-main\src\bot.py", line 318, in run
    client = SafeClient(api_key, api_secret, testnet=use_testnet)
  File "d:\binance_ats_clone\obaidur-binance-ats-main\src\safe_client.py", line 74, in __init__
    self._client = Client(api_key, api_secret, testnet=testnet)
                   ~~~~~~^^^^^^^^^^^^^^^^^^^^^^^^^^^^^^^^^^^^^^
  File "D:\binance_ats_clone\obaidur-binance-ats-main\.venv\.venv\Lib\site-packages\binance\client.py", line 51, in __init__
    self.ping()
    ~~~~~~~~~^^
  File "D:\binance_ats_clone\obaidur-binance-ats-main\.venv\.venv\Lib\site-packages\binance\client.py", line 344, in ping
    return self._get("ping", version=self.PRIVATE_API_VERSION)
           ~~~~~~~~~^^^^^^^^^^^^^^^^^^^^^^^^^^^^^^^^^^^^^^^^^^
  File "D:\binance_ats_clone\obaidur-binance-ats-main\.venv\.venv\Lib\site-packages\binance\client.py", line 180, in _get
    return self._request_api("get", path, signed, version, **kwargs)
           ~~~~~~~~~~~~~~~~~^^^^^^^^^^^^^^^^^^^^^^^^^^^^^^^^^^^^^^^^
  File "D:\binance_ats_clone\obaidur-binance-ats-main\.venv\.venv\Lib\site-packages\binance\client.py", line 117, in _request_api
    return self._request(method, uri, signed, **kwargs)
           ~~~~~~~~~~~~~^^^^^^^^^^^^^^^^^^^^^^^^^^^^^^^
  File "D:\binance_ats_clone\obaidur-binance-ats-main\.venv\.venv\Lib\site-packages\binance\client.py", line 88, in _request
    self.response = getattr(self.session, method)(uri, headers=headers, data=data, **kwargs)
                    ~~~~~~~~~~~~~~~~~~~~~~~~~~~~~^^^^^^^^^^^^^^^^^^^^^^^^^^^^^^^^^^^^^^^^^^^
  File "D:\binance_ats_clone\obaidur-binance-ats-main\.venv\.venv\Lib\site-packages\requests\sessions.py", line 602, in get
    return self.request("GET", url, **kwargs)
           ~~~~~~~~~~~~^^^^^^^^^^^^^^^^^^^^^^
  File "D:\binance_ats_clone\obaidur-binance-ats-main\.venv\.venv\Lib\site-packages\requests\sessions.py", line 589, in request
    resp = self.send(prep, **send_kwargs)
  File "D:\binance_ats_clone\obaidur-binance-ats-main\.venv\.venv\Lib\site-packages\requests\sessions.py", line 703, in send
    r = adapter.send(request, **kwargs)
  File "D:\binance_ats_clone\obaidur-binance-ats-main\.venv\.venv\Lib\site-packages\requests\adapters.py", line 677, in send
    raise ConnectionError(e, request=request)
requests.exceptions.ConnectionError: HTTPSConnectionPool(host='testnet.binance.vision', port=443): Max retries exceeded with url: /api/v3/ping (Caused by NameResolutionError("<urllib3.connection.HTTPSConnection object at 0x0000025F830291D0>: Failed to resolve 'testnet.binance.vision' ([Errno 11001] getaddrinfo failed)"))
